Workbook

Sheet How to Use
A1: HOW TO USE THIS WORKBOOK
A3: 1. These are generic test cases for a typical ASP.NET Core MVC + EF app (register, login, CRUD, search, security).
A4: 2. Replace [Controller], [Entity] and field names with your app's real names. Delete test cases for features your app does not have.
A5: 3. Fill in real Test Data (e.g., actual usernames and your field max lengths) before you run each test.
A6: 4. Record each test in Selenium IDE using the name in column L, then run it.
A7: 5. Write what really happened in 'Actual Result' (column J) and choose Pass / Fail / Blocked in 'Status' (column K).
A8: 6. If a test fails because of a real app problem, log it in the 'Bug Report' sheet (a sample row is given in grey).
A9: 7. The 'Summary' sheet updates automatically from the Status column.
A11: Test types: Positive = valid data works | Negative = invalid data is rejected | Boundary = limits (min/max) | Security = misuse attempts
A12: Priority: High = core feature, test first | Medium = important | Low = nice to verify

Sheet Test Cases
A1: Test Case ID | B1: Module | C1: Scenario | D1: Test Type | E1: Priority | F1: Preconditions | G1: Test Steps | H1: Test Data | I1: Expected Result | J1: Actual Result | K1: Status | L1: Selenium IDE Test Name | M1: Remarks
A2: TC01 | B2: Registration | C2: Register with all valid details | D2: Positive | E2: High | F2: App running; user not registered | G2: 1. Open Register page 2. Enter valid email, password, confirm password 3. Click Register | H2: Email: qauser1@mail.com Password: Test@1234 | I2: Account created; user redirected to Home/Login page | J2: user created successfully | K2: Pass | L2: T1-Registration
A3: TC02 | B3: Registration | C3: Register with an already registered email | D3: Negative | E3: High | F3: qauser1@mail.com already exists | G3: 1. Open Register page 2. Enter existing email and valid password 3. Click Register | H3: Email: qauser1@mail.com Password: Test@1234 | I3: Error shown that the email/username is already taken; no duplicate account created | J3: username is already taken | K3: Pass | L3: T1-Registration
A4: TC03 | B4: Registration | C4: Register with empty fields | D4: Negative | E4: High | F4: Register page open | G4: 1. Leave all fields blank 2. Click Register | H4: All fields blank | I4: 'Required' validation message shown for each field; form not submitted | J4: the required field were indicated | K4: Pass | L4: T1-Registration
A5: TC04 | B5: Registration | C5: Register with invalid email format | D5: Negative | E5: Medium | F5: Register page open | G5: 1. Enter email without '@' 2. Enter valid password 3. Click Register | H5: Email: qauser.mail.com | I5: Invalid email format error shown; account not created | J5: while entering itself it is notified as error | K5: Pass | L5: T1-Registration
A6: TC05 | B6: Registration | C6: Password and Confirm Password do not match | D6: Negative | E6: High | F6: Register page open | G6: 1. Enter valid email 2. Enter different password and confirm password 3. Click Register | H6: Password: Test@1234 Confirm: Test@9999 | I6: 'Passwords do not match' error shown | J6: it was notified even while entering | K6: Pass | L6: T1-Registration
A7: TC06 | B7: Registration | C7: Password shorter than minimum length | D7: Boundary | E7: Medium | F7: Register page open | G7: 1. Enter valid email 2. Enter a very short password 3. Click Register | H7: Password: Ab@1 | I7: Password policy error shown; account not created | J7: passwd must haves: 1< digits, 1<uppercase | K7: Pass | L7: T1-Registration
A8: TC07 | B8: Login | C8: Login with valid credentials | D8: Positive | E8: High | F8: User account exists | G8: 1. Open Login page 2. Enter valid username and password 3. Click Login | H8: Valid registered user | I8: User logged in; Home/Dashboard page shown with user name or Logout link | J8: logged in and directed to home page | K8: Pass | L8: T2-Login
A9: TC08 | B9: Login | C9: Login with wrong password | D9: Negative | E9: High | F9: User account exists | G9: 1. Open Login page 2. Enter valid username and wrong password 3. Click Login | H9: Username: valid Password: Wrong@123 | I9: 'Invalid login attempt' error shown; user stays on Login page | J9: shown invalid login attempt | K9: Pass | L9: T2-Login
A10: TC09 | B10: Login | C10: Login with unregistered username | D10: Negative | E10: High | F10: Login page open | G10: 1. Enter a username that does not exist 2. Enter any password 3. Click Login | H10: Username: nouser@mail.com Password: Test@1234 | I10: 'Invalid login attempt' error shown; no account details revealed | J10: username doesn’t exists | K10: Pass | L10: T2-Login
A11: TC10 | B11: Login | C11: Login with both fields empty | D11: Negative | E11: High | F11: Login page open | G11: 1. Leave username and password blank 2. Click Login | H11: Blank | I11: 'Required' validation messages shown for both fields | J11: doesn’t allow to click the login button without details and messages shown | K11: Pass | L11: T2-Login
A12: TC11 | B12: Login | C12: Login with only username filled | D12: Negative | E12: Medium | F12: Login page open | G12: 1. Enter username only 2. Leave password blank 3. Click Login | H12: Username: valid Password: blank | I12: Password 'Required' message shown; login blocked | J12: validation message shown | K12: Pass | L12: T2-Login
A13: TC12 | B13: Login | C13: Login with only password filled | D13: Negative | E13: Medium | F13: Login page open | G13: 1. Leave username blank 2. Enter password 3. Click Login | H13: Username: blank Password: Test@1234 | I13: Username 'Required' message shown; login blocked | J13: validation message shown | K13: Pass | L13: T2-Login
... A19: TC18 | B19: Authorization | C19: Access protected page without login | D19: Security | E19: High | F19: User not logged in | G19: 1. Paste URL of a protected page (e.g., /Product/Create) in the address bar 2. Press Enter | H19: Direct URL | I19: User redirected to Login page; page content not shown | J19: user directed to login page | K19: Pass | L19: TC18_Access_protected_page_without_login
A20: TC20 | B20: Navigation Testing | C20: Admin home page loads after login | D20: Positive | E20: High | F20: Logged in as Admin | G20: 1. Log in with admin credentials 2. Observe the page that opens | H20: Admin credentials | I20: Home page opens; admin menu items are visible; no errors | K20: Not Run | L20: TC20_Admin_home_page_loads_after_login
A21: TC21 | B21: Navigation Testing | C21: Admin navbar shows all admin menu options | D21: Positive | E21: High | F21: Logged in as Admin | G21: 1. Look at the top navigation bar | H21: None | I21: Category, Order, Cart (and other admin links) are visible to admin | K21: Not Run | L21: TC21_Admin_navbar_shows_all_admin_menu_o
A22: TC22 | B22: Navigation Testing | C22: Category menu opens Category List | D22: Positive | E22: High | F22: Logged in as Admin | G22: 1. Click Category in the navbar | H22: None | I22: Category List page opens with heading 'Category List' | K22: Not Run | L22: TC22_Category_menu_opens_Category_List
A23: TC23 | B23: Navigation Testing | C23: Order menu opens Order list | D23: Positive | E23: High | F23: Logged in as Admin | G23: 1. Click Order / Manage Order in the navbar | H23: None | I23: Order list page opens; no error | K23: Not Run | L23: TC23_Order_menu_opens_Order_list
A24: TC24 | B24: Navigation Testing | C24: Cart menu opens Cart page | D24: Positive | E24: Medium | F24: Logged in as Admin | G24: 1. Click Cart in the navbar | H24: None | I24: Cart page opens; no error | K24: Not Run | L24: TC24_Cart_menu_opens_Cart_page
A25: TC25 | B25: Navigation Testing | C25: Create New Category button opens Create page | D25: Positive | E25: High | F25: Logged in as Admin; on Category List | G25: 1. Click 'Create New Category' | H25: None | I25: Create Category form opens | K25: Not Run | L25: TC25_Create_New_Category_button_opens_Cr
A26: TC26 | B26: Navigation Testing | C26: Edit button opens Edit page of the same category | D26: Positive | E26: High | F26: Logged in as Admin; categories exist | G26: 1. Click Edit beside a category | H26: One category | I26: Edit page opens showing that category's data | K26: Not Run | L26: TC26_Edit_button_opens_Edit_page_of_the
A27: TC27 | B27: Navigation Testing | C27: Delete button opens Delete page of the same category | D27: Positive | E27: High | F27: Logged in as Admin; categories exist | G27: 1. Click Delete beside a category | H27: One category | I27: Delete confirmation page opens for that category | K27: Not Run | L27: TC27_Delete_button_opens_Delete_page_of
A28: TC28 | B28: Navigation Testing | C28: Back to List link returns to Category List | D28: Positive | E28: Medium | F28: Logged in as Admin; on Create/Edit page | G28: 1. Click 'Back to List' | H28: None | I28: Category List opens; no changes saved | K28: Not Run | L28: TC28_Back_to_List_link_returns_to_Catego
A29: TC29 | B29: Navigation Testing | C29: Browser Back and Forward buttons work | D29: Positive | E29: Medium | F29: Logged in as Admin | G29: 1. Open Category List, then Create page 2. Click browser Back 3. Click browser Forward | H29: None | I29: Correct pages open each time; no error page | K29: Not Run | L29: TC29_Browser_Back_and_Forward_buttons_wo
A30: TC30 | B30: Navigation Testing | C30: Logo / app name returns to Home | D30: Positive | E30: Low | F30: Logged in as Admin; on an inner page | G30: 1. Click the logo or app name | H30: None | I30: Home page opens | K30: Not Run | L30: TC30_Logo___app_name_returns_to_Home
A31: TC31 | B31: Navigation Testing | C31: Direct URL of an admin page works while logged in | D31: Positive | E31: Medium | F31: Logged in as Admin | G31: 1. Type the Category List URL in the address bar 2. Press Enter | H31: Base URL + /Category | I31: Category List opens without asking to log in again | K31: Not Run | L31: TC31_Direct_URL_of_an_admin_page_works_w
... A40: TC40 | B40: Category Testing | C40: Create with Display Order empty | D40: Negative | E40: High | F40: Logged in as Admin | G40: 1. Enter valid Name 2. Leave Display Order blank 3. Click Create | H40: Name: QA_Cat_02 Display Order: blank | I40: Display Order 'required' message shown; nothing saved | K40: Not Run | L40: TC40_Create_with_Display_Order_empty
A41: TC41 | B41: Category Testing | C41: Name longer than the maximum length | D41: Boundary | E41: High | F41: Logged in as Admin | G41: 1. Enter a Name longer than the allowed limit 2. Enter valid Display Order 3. Click Create | H41: Name: maximum + 1 characters | I41: Length validation error shown; nothing saved | K41: Not Run | L41: TC41_Name_longer_than_the_maximum_length | M41: Check your model for the real limit (for example [MaxLength(30)])
A42: TC42 | B42: Category Testing | C42: Name exactly at the maximum length | D42: Boundary | E42: Medium | F42: Logged in as Admin | G42: 1. Enter a Name of exactly the maximum length 2. Click Create | H42: Name: maximum characters | I42: Category saved successfully | K42: Not Run | L42: TC42_Name_exactly_at_the_maximum_length | M42: Check your model for the real limit
A43: TC43 | B43: Category Testing | C43: Display Order with letters | D43: Negative | E43: High | F43: Logged in as Admin | G43: 1. Enter a valid Name 2. Type letters in Display Order 3. Click Create | H43: Display Order: abc | I43: Validation error shown; nothing saved | K43: Not Run | L43: TC43_Display_Order_with_letters
A44: TC44 | B44: Category Testing | C44: Display Order below the minimum | D44: Boundary | E44: High | F44: Logged in as Admin | G44: 1. Enter valid Name 2. Enter 0 in Display Order 3. Click Create | H44: Display Order: 0 | I44: Range error shown; nothing saved | K44: Not Run | L44: TC44_Display_Order_below_the_minimum | M44: Use the real range from your model, for example [Range(1,100)]
A45: TC45 | B45: Category Testing | C45: Display Order above the maximum | D45: Boundary | E45: High | F45: Logged in as Admin | G45: 1. Enter valid Name 2. Enter a value above the maximum 3. Click Create | H45: Display Order: 101 | I45: Range error shown; nothing saved | K45: Not Run | L45: TC45_Display_Order_above_the_maximum | M45: Use the real range from your model
A46: TC46 | B46: Category Testing | C46: Display Order at the minimum and maximum limits | D46: Boundary | E46: Medium | F46: Logged in as Admin | G46: 1. Create a category with the lowest allowed Display Order 2. Create another with the highest allowed | H46: Display Order: 1 and 100 | I46: Both saved successfully | K46: Not Run | L46: TC46_Display_Order_at_the_minimum_and_ma | M46: Use the real range from your model
A47: TC47 | B47: Category Testing | C47: Negative Display Order | D47: Negative | E47: Medium | F47: Logged in as Admin | G47: 1. Enter valid Name 2. Enter -5 in Display Order 3. Click Create | H47: Display Order: -5 | I47: Validation error shown; nothing saved | K47: Not Run | L47: TC47_Negative_Display_Order
A48: TC48 | B48: Category Testing | C48: Duplicate category name | D48: Negative | E48: High | F48: Logged in as Admin; category 'Fiction' exists | G48: 1. Enter an existing Name 2. Enter valid Display Order 3. Click Create | H48: Name: Fiction | I48: Behaves as per business rule: error shown, or duplicate allowed if no rule exists | K48: Not Run | L48: TC48_Duplicate_category_name | M48: Note the actual behaviour. If duplicates are allowed, raise it as a bug/observation
A49: TC49 | B49: Category Testing | C49: Name with only spaces | D49: Negative | E49: Medium | F49: Logged in as Admin | G49: 1. Type spaces only in Name 2. Enter valid Display Order 3. Click Create | H49: Name: ' ' | I49: Treated as empty; required error shown | K49: Not Run | L49: TC49_Name_with_only_spaces
A50: TC50 | B50: Category Testing | C50: Name with special characters | D50: Negative | E50: Medium | F50: Logged in as Admin | G50: 1. Enter special characters in Name 2. Click Create | H50: Name: @#$%^&* | I50: Saved or rejected as per rules; no crash; displays correctly in list | K50: Not Run | L50: TC50_Name_with_special_characters
A51: TC51 | B51: Category Testing | C51: Cancel create using Back to List | D51: Positive | E51: Low | F51: Logged in as Admin | G51: 1. Fill the form partly 2. Click Back to List | H51: Partial data | I51: Returns to list; no new category saved | K51: Not Run | L51: TC51_Cancel_create_using_Back_to_List
A52: TC52 | B52: Category Testing | C52: Edit page shows existing values | D52: Positive | E52: Medium | F52: Logged in as Admin; category exists | G52: 1. Click Edit on a category | H52: One category | I52: Name and Display Order are pre-filled with current values | K52: Not Run | L52: TC52_Edit_page_shows_existing_values
A53: TC53 | B53: Category Testing | C53: Edit with valid new values | D53: Positive | E53: High | F53: Logged in as Admin; category exists | G53: 1. Click Edit 2. Change Name and Display Order 3. Click Update | H53: Name: QA_Cat_01_Edited Display Order: 78 | I53: Changes saved; new values visible in list | K53: Not Run | L53: TC53_Edit_with_valid_new_values
...

Sheet Summary
A1: Test Execution Summary
A3: Total Test Cases | B3: =COUNTA('Test Cases'!A2:A51) -> 50
A4: Passed | B4: =COUNTIF('Test Cases'!K2:K51,"Pass") -> 18
A5: Failed | B5: =COUNTIF('Test Cases'!K2:K51,"Fail") -> 0
A6: Blocked | B6: =COUNTIF('Test Cases'!K2:K51,"Blocked") -> 0
A7: Not Run | B7: =COUNTIF('Test Cases'!K2:K51,"Not Run") -> 32
A8: Pass % (of executed) | B8: =IF((B3-B7)=0,0,B4/(B3-B7)) -> 1
A10: By Test Type
A11: Positive | B11: =COUNTIF('Test Cases'!D2:D51,A11) -> 21
A12: Negative | B12: =COUNTIF('Test Cases'!D2:D51,A12) -> 19
A13: Boundary | B13: =COUNTIF('Test Cases'!D2:D51,A13) -> 6
A14: Security | B14: =COUNTIF('Test Cases'!D2:D51,A14) -> 3
A16: By Priority
A17: High | B17: =COUNTIF('Test Cases'!E2:E51,A17) -> 29
A18: Medium | B18: =COUNTIF('Test Cases'!E2:E51,A18) -> 16
A19: Low | B19: =COUNTIF('Test Cases'!E2:E51,A19) -> 5
A21: By Module
A22: Registration | B22: =COUNTIF('Test Cases'!B2:B51,A22) -> 6
A23: Login | B23: =COUNTIF('Test Cases'!B2:B51,A23) -> 9
A24: Logout | B24: =COUNTIF('Test Cases'!B2:B51,A24) -> 2
A25: Authorization | B25: =COUNTIF('Test Cases'!B2:B51,A25) -> 1
A26: Navigation | B26: =COUNTIF('Test Cases'!B2:B51,A26) -> 0
A27: Create | B27: =COUNTIF('Test Cases'!B2:B51,A27) -> 0
A28: List / Read | B28: =COUNTIF('Test Cases'!B2:B51,A28) -> 0
A29: Search / Filter | B29: =COUNTIF('Test Cases'!B2:B51,A29) -> 0
A30: Edit | B30: =COUNTIF('Test Cases'!B2:B51,A30) -> 0
A31: Delete | B31: =COUNTIF('Test Cases'!B2:B51,A31) -> 0
A32: End-to-End | B32: =COUNTIF('Test Cases'!B2:B51,A32) -> 0
A33: Security | B33: =COUNTIF('Test Cases'!B2:B51,A33) -> 0
A34: UI / Usability | B34: =COUNTIF('Test Cases'!B2:B51,A34) -> 0
A35: Compatibility | B35: =COUNTIF('Test Cases'!B2:B51,A35) -> 0
A36: Performance | B36: =COUNTIF('Test Cases'!B2:B51,A36) -> 0
A37: Session | B37: =COUNTIF('Test Cases'!B2:B51,A37) -> 0

Sheet Bug Report
A1: Bug ID | B1: Linked Test Case | C1: Title | D1: Steps to Reproduce | E1: Expected Result | F1: Actual Result | G1: Severity | H1: Priority | I1: Status | J1: Screenshot File Name
A2: BUG-01 (example) | B2: TC23 | C2: Record not saved when all fields are valid | D2: 1. Login 2. Click Create New 3. Fill valid data 4. Click Create | E2: Record saved and shown in list | F2: Error page shown | G2: High | H2: High | I2: Open | J2: bug01.png
